2024-03-30 20:41:02,156 WARNING Сообщения уровня WARNING, не критичны, но проблема может повторится
2024-03-30 20:41:02,157 ERROR Сообщения уровня ERROR, программа не смогла выполнить какую-либо функцию
2024-03-30 20:41:02,157 CRITICAL Сообщения уровня CRITICAL, серьезная ошибка нарушающая дальнейшую работу
2024-03-30 20:43:26,888 ERROR Cause exception while process update id=401813227 by bot id=6907852509
UndefinedColumnError: столбец "code" не существует
Traceback (most recent call last):
  File "C:\Python312\Lib\site-packages\aiogram\dispatcher\dispatcher.py", line 309, in _process_update
    response = await self.feed_update(bot, update, **kwargs)
               ^^^^^^^^^^^^^^^^^^^^^^^^^^^^^^^^^^^^^^^^^^^^^
  File "C:\Python312\Lib\site-packages\aiogram\dispatcher\dispatcher.py", line 158, in feed_update
    response = await self.update.wrap_outer_middleware(
               ^^^^^^^^^^^^^^^^^^^^^^^^^^^^^^^^^^^^^^^^
  File "C:\Python312\Lib\site-packages\aiogram\dispatcher\middlewares\error.py", line 25, in __call__
    return await handler(event, data)
           ^^^^^^^^^^^^^^^^^^^^^^^^^^
  File "C:\Python312\Lib\site-packages\aiogram\dispatcher\middlewares\user_context.py", line 27, in __call__
    return await handler(event, data)
           ^^^^^^^^^^^^^^^^^^^^^^^^^^
  File "C:\Python312\Lib\site-packages\aiogram\fsm\middleware.py", line 41, in __call__
    return await handler(event, data)
           ^^^^^^^^^^^^^^^^^^^^^^^^^^
  File "C:\Python312\Lib\site-packages\aiogram\dispatcher\event\telegram.py", line 121, in trigger
    return await wrapped_inner(event, kwargs)
           ^^^^^^^^^^^^^^^^^^^^^^^^^^^^^^^^^^
  File "C:\Python312\Lib\site-packages\aiogram\dispatcher\event\handler.py", line 43, in call
    return await wrapped()
           ^^^^^^^^^^^^^^^
  File "C:\Python312\Lib\site-packages\aiogram\dispatcher\dispatcher.py", line 276, in _listen_update
    return await self.propagate_event(update_type=update_type, event=event, **kwargs)
           ^^^^^^^^^^^^^^^^^^^^^^^^^^^^^^^^^^^^^^^^^^^^^^^^^^^^^^^^^^^^^^^^^^^^^^^^^^
  File "C:\Python312\Lib\site-packages\aiogram\dispatcher\router.py", line 116, in propagate_event
    return await observer.wrap_outer_middleware(_wrapped, event=event, data=kwargs)
           ^^^^^^^^^^^^^^^^^^^^^^^^^^^^^^^^^^^^^^^^^^^^^^^^^^^^^^^^^^^^^^^^^^^^^^^^
  File "C:\Python312\Lib\site-packages\aiogram\dispatcher\router.py", line 111, in _wrapped
    return await self._propagate_event(
           ^^^^^^^^^^^^^^^^^^^^^^^^^^^^
  File "C:\Python312\Lib\site-packages\aiogram\dispatcher\router.py", line 144, in _propagate_event
    response = await router.propagate_event(update_type=update_type, event=event, **kwargs)
               ^^^^^^^^^^^^^^^^^^^^^^^^^^^^^^^^^^^^^^^^^^^^^^^^^^^^^^^^^^^^^^^^^^^^^^^^^^^^
  File "C:\Python312\Lib\site-packages\aiogram\dispatcher\router.py", line 116, in propagate_event
    return await observer.wrap_outer_middleware(_wrapped, event=event, data=kwargs)
           ^^^^^^^^^^^^^^^^^^^^^^^^^^^^^^^^^^^^^^^^^^^^^^^^^^^^^^^^^^^^^^^^^^^^^^^^
  File "C:\Python312\Lib\site-packages\aiogram\dispatcher\router.py", line 111, in _wrapped
    return await self._propagate_event(
           ^^^^^^^^^^^^^^^^^^^^^^^^^^^^
  File "C:\Python312\Lib\site-packages\aiogram\dispatcher\router.py", line 144, in _propagate_event
    response = await router.propagate_event(update_type=update_type, event=event, **kwargs)
               ^^^^^^^^^^^^^^^^^^^^^^^^^^^^^^^^^^^^^^^^^^^^^^^^^^^^^^^^^^^^^^^^^^^^^^^^^^^^
  File "C:\Python312\Lib\site-packages\aiogram\dispatcher\router.py", line 116, in propagate_event
    return await observer.wrap_outer_middleware(_wrapped, event=event, data=kwargs)
           ^^^^^^^^^^^^^^^^^^^^^^^^^^^^^^^^^^^^^^^^^^^^^^^^^^^^^^^^^^^^^^^^^^^^^^^^
  File "C:\Python312\Lib\site-packages\aiogram\dispatcher\router.py", line 111, in _wrapped
    return await self._propagate_event(
           ^^^^^^^^^^^^^^^^^^^^^^^^^^^^
  File "C:\Python312\Lib\site-packages\aiogram\dispatcher\router.py", line 136, in _propagate_event
    response = await observer.trigger(event, **kwargs)
               ^^^^^^^^^^^^^^^^^^^^^^^^^^^^^^^^^^^^^^^
  File "C:\Python312\Lib\site-packages\aiogram\dispatcher\event\telegram.py", line 121, in trigger
    return await wrapped_inner(event, kwargs)
           ^^^^^^^^^^^^^^^^^^^^^^^^^^^^^^^^^^
  File "C:\Python312\Lib\site-packages\aiogram\dispatcher\event\handler.py", line 43, in call
    return await wrapped()
           ^^^^^^^^^^^^^^^
  File "C:\Users\Dins\Desktop\Python\NIL-URL\core\handlers\url.py", line 52, in url_name
    if not(await table_url.get(code = code)):
           ^^^^^^^^^^^^^^^^^^^^^^^^^^^^^^^^
  File "C:\Users\Dins\Desktop\Python\NIL-URL\core\database\Models.py", line 52, in get
    params = await connection.fetch(f"SELECT {data} FROM {self.table} WHERE {' AND '.join(query)} ;")
             ^^^^^^^^^^^^^^^^^^^^^^^^^^^^^^^^^^^^^^^^^^^^^^^^^^^^^^^^^^^^^^^^^^^^^^^^^^^^^^^^^^^^^^^^
  File "C:\Python312\Lib\site-packages\asyncpg\connection.py", line 691, in fetch
    return await self._execute(
           ^^^^^^^^^^^^^^^^^^^^
  File "C:\Python312\Lib\site-packages\asyncpg\connection.py", line 1794, in _execute
    result, _ = await self.__execute(
                ^^^^^^^^^^^^^^^^^^^^^
  File "C:\Python312\Lib\site-packages\asyncpg\connection.py", line 1892, in __execute
    result, stmt = await self._do_execute(
                   ^^^^^^^^^^^^^^^^^^^^^^^
  File "C:\Python312\Lib\site-packages\asyncpg\connection.py", line 1925, in _do_execute
    stmt = await self._get_statement(
           ^^^^^^^^^^^^^^^^^^^^^^^^^^
  File "C:\Python312\Lib\site-packages\asyncpg\connection.py", line 433, in _get_statement
    statement = await self._protocol.prepare(
                ^^^^^^^^^^^^^^^^^^^^^^^^^^^^^
  File "asyncpg\protocol\protocol.pyx", line 166, in prepare
asyncpg.exceptions.UndefinedColumnError: столбец "code" не существует
2024-03-30 20:44:08,162 WARNING Сообщения уровня WARNING, не критичны, но проблема может повторится
2024-03-30 20:44:08,162 ERROR Сообщения уровня ERROR, программа не смогла выполнить какую-либо функцию
2024-03-30 20:44:08,162 CRITICAL Сообщения уровня CRITICAL, серьезная ошибка нарушающая дальнейшую работу
2024-03-30 21:11:34,565 WARNING Сообщения уровня WARNING, не критичны, но проблема может повторится
2024-03-30 21:11:34,565 ERROR Сообщения уровня ERROR, программа не смогла выполнить какую-либо функцию
2024-03-30 21:11:34,565 CRITICAL Сообщения уровня CRITICAL, серьезная ошибка нарушающая дальнейшую работу
2024-03-30 21:13:46,223 WARNING Сообщения уровня WARNING, не критичны, но проблема может повторится
2024-03-30 21:13:46,223 ERROR Сообщения уровня ERROR, программа не смогла выполнить какую-либо функцию
2024-03-30 21:13:46,223 CRITICAL Сообщения уровня CRITICAL, серьезная ошибка нарушающая дальнейшую работу
2024-03-30 21:14:08,924 WARNING Сообщения уровня WARNING, не критичны, но проблема может повторится
2024-03-30 21:14:08,924 ERROR Сообщения уровня ERROR, программа не смогла выполнить какую-либо функцию
2024-03-30 21:14:08,924 CRITICAL Сообщения уровня CRITICAL, серьезная ошибка нарушающая дальнейшую работу
2024-03-30 23:38:22,634 ERROR Failed to fetch updates - TelegramNetworkError: HTTP Client says - Request timeout error
2024-03-30 23:38:22,635 WARNING Sleep for 1.000000 seconds and try again... (tryings = 0, bot id = 6907852509)
